Workbook

Sheet SourcedData
A1: data_key | B1: sheet | C1: orig_row | D1: section | E1: item | F1: unit | G1: anglo_share_pct | H1: source_ref | I1: comment | J1: Q1_2012 | K1: Q2_2012 | L1: Q3_2012 | M1: Q4_2012 | N1: Q1_2013 | O1: Q2_2013 | P1: Q3_2013 | Q1: Q4_2013 | R1: Q1_2014 | S1: Q2_2014 | T1: Q3_2014 | U1: Q4_2014 | V1: Q1_2015 | W1: Q2_2015 | X1: Q3_2015 | Y1: Q4_2015 | Z1: Q1_2016 | AA1: Q2_2016 | AB1: Q3_2016 | AC1: Q4_2016 | AD1: Q1_2017 | AE1: Q2_2017 | AF1: Q3_2017 | AG1: Q4_2017 | AH1: Q1_2018 | AI1: Q2_2018 | AJ1: Q3_2018 | AK1: Q4_2018 | AL1: Q1_2019 | AM1: Q2_2019 | AN1: Q3_2019 | AO1: Q4_2019 | AP1: Q1_2020 | AQ1: Q2_2020 | AR1: Q3_2020 | AS1: Q4_2020 | AT1: Q1_2021 | AU1: Q2_2021 | AV1: Q3_2021 | AW1: Q4_2021 | AX1: Q1_2022 | AY1: Q2_2022 | AZ1: Q3_2022 | BA1: Q4_2022 | BB1: Q1_2023 | BC1: Q2_2023 | BD1: Q3_2023 | BE1: Q4_2023 | BF1: Q1_2024 | BG1: Q2_2024 | BH1: Q3_2024 | BI1: Q4_2024 | BJ1: Q1_2025 | BK1: Q2_2025 | BL1: Q3_2025 | BM1: Q4_2025 | BN1: FY2012_2013 | BO1: FY2013_2014 | BP1: FY2014_2015 | BQ1: FY2015_2016 | BR1: FY2016_2017 | BS1: FY2017_2018 | BT1: FY2018_2019 | BU1: FY2019_2020 | BV1: FY2020_2021 | BW1: FY2021_2022 | BX1: FY2022_2023 | BY1: FY2023_2024 | BZ1: FY2024_2025 | CA1: FY2025_2026 | CB1: CY2012 | CC1: CY2013 | CD1: CY2014 | CE1: CY2015 | CF1: CY2016 | CG1: CY2017 | CH1: CY2018 | CI1: CY2019 | CJ1: CY2020 | CK1: CY2021 | CL1: CY2022 | CM1: CY2023 | CN1: CY2024
A2: Coal production - Mine Level::Callide | B2: VariousOperations_Calculations | C2: 10 | D2: Coal production - Mine Level | E2: Callide | F2: Mt | G2: 100 | H2: MLCCI-1639775051-8792 | I2: Total production on 100% basis. Sold end of 2016 | N2: 1.1514 | O2: 1.7253 | P2: 1.7523 | Q2: 1.6888 | R2: 1.2292 | S2: 1.8446 | T2: 2.3185 | U2: 2.1647 | V2: 1.857 | W2: 1.7893 | X2: 1.9889 | Y2: 2.2952 | Z2: 1.7482 | AA2: 1.8053 | AB2: 1.9389 | AC2: 0.7384 | CB2: 7.464
A3: Coal production - Mine Level::Capcoal (Grasstree, Lake Lindsay and Aquila mines) | B3: VariousOperations_Calculations | C3: 11 | D3: Coal production - Mine Level | E3: Capcoal (Grasstree, Lake Lindsay and Aquila mines) | F3: Mt | G3: 70 | H3: MLCCI-6-1112 | I3: Total production on 100% basis; calculated using attributable production and % stake of the company in mine; Calculated using sum of quarterly figures except for 2012; For 2012 calendar year is considered and calculated using attributable production and % stake of the company in mine | N3: 1.4155 | O3: 1.4611 | P3: 1.606 | Q3: 1.5788 | R3: 1.9047 | S3: 1.8475 | T3: 1.8163 | U3: 2.0743 | V3: 2.2591 | W3: 1.7935 | X3: 2.3533 | Y3: 2.2838 | Z3: 1.76 | AA3: 2.2054 | AB3: 1.6373 | AC3: 1.2302 | CB3: 6.0224
A4: Coal production - Mine Level::Dawson | B4: VariousOperations_Calculations | C4: 12 | D4: Coal production - Mine Level | E4: Dawson | F4: Mt | G4: 51 | H4: MLCCI-6-1112 | I4: Total production on 100% basis; calculated using attributable production and % stake of the company in mine; Calculated using sum of quarterly figures except for 2012; For 2012 calendar year is considered and calculated using attributable production and % stake of the company in mine | N4: 0.7526 | O4: 1.0771 | P4: 0.9933 | Q4: 1.1627 | R4: 1.0228 | S4: 1.1012 | T4: 1.0414 | U4: 1.0748 | V4: 0.6638 | W4: 1.3755 | X4: 1.2494 | Y4: 1.0258 | Z4: 1.006 | AA4: 1.1438 | AB4: 1.1859 | AC4: 1.273 | AD4: 1.0921 | AE4: 1.0468 | AF4: 1.0128 | AG4: 0.6305 | CB4: 4.5935
A5: Coal production - Mine Level::Drayton | B5: VariousOperations_Calculations | C5: 13 | D5: Coal production - Mine Level | E5: Drayton | F5: Mt | G5: 88 | H5: MLCCI-6-1112 | I5: Total production on 100% basis; calculated using attributable production and % stake of the company in mine; Calculated using sum of quarterly figures except for 2012; For 2012 calendar year is considered and calculated using attributable production and % stake of the company in mine; Ceased mining activities at the Drayton mine in 2016. | N5: 0.8934 | O5: 0.785 | P5: 1.0559 | Q5: 0.9764 | R5: 0.6591 | S5: 0.7085 | T5: 0.817 | U5: 0.9202 | V5: 0.7075 | W5: 0.4628 | X5: 0.6004 | Y5: 0.3513 | Z5: 0.3499 | AA5: 0.4182 | AB5: 0.3171 | AC5: 0.0823 | CB5: 3.6633
A6: Coal production - Mine Level::Foxleigh | B6: VariousOperations_Calculations | C6: 14 | D6: Coal production - Mine Level | E6: Foxleigh | F6: Mt | G6: 70 | H6: MLCCI-1639775051-8792 | I6: Total production on 100% basis; calculated using attributable production and % stake of the company in mine; Calculated using sum of quarterly figures except for 2012; For 2012 calendar year is considered and calculated using attributable production and % stake of the company in mine. SOld end of 2016 | N6: 0.528 | O6: 0.4757 | P6: 0.541 | Q6: 0.4219 | R6: 0.4329 | S6: 0.4712 | T6: 0.5512 | U6: 0.5792 | V6: 0.4783 | W6: 0.5112 | X6: 0.4948 | Y6: 0.3763 | Z6: 0.4345 | AA6: 0.566 | AB6: 0.4389 | CB6: 1.896
A7: Coal production - Mine Level::Jellinbah Group (Lake Vermont and Jellinbah East) | B7: VariousOperations_Calculations | C7: 15 | D7: Coal production - Mine Level | E7: Jellinbah Group (Lake Vermont and Jellinbah East) | F7: Mt | G7: 23.3 | H7: MLCCI-6-1112 | I7: Total production on 100% basis; calculated using attributable production and % stake of the company in mine; Calculated using sum of quarterly figures except for 2012; For 2012 calendar year is considered and calculated using attributable production and % stake of the company in mine | N7: 0.4772 | O7: 0.61 | P7: 0.6734 | Q7: 0.7559 | R7: 0.6775 | S7: 0.7563 | T7: 0.7328 | U7: 0.7571 | V7: 0.7639 | W7: 0.7664 | X7: 0.7984 | Y7: 0.8727 | Z7: 0.7584 | AA7: 0.8216 | AB7: 0.8202 | AC7: 0.8821 | AD7: 0.718 | AE7: 0.8403 | AF7: 0.8367 | AG7: 0.8606 | CB7: 2.0732
A8: Coal production - Mine Level::Moranbah North | B8: VariousOperations_Calculations | C8: 16 | D8: Coal production - Mine Level | E8: Moranbah North | F8: Mt | G8: 88 | H8: MLCCI-1639775051-8792 | I8: Total production on 100% basis; calculated using attributable production and % stake of the company in mine; Calculated using sum of quarterly figures except for 2012; For 2012 calendar year is considered and calculated using attributable production and % stake of the company in mine | N8: 1.4998 | O8: 1.0514 | P8: 1.3005 | Q8: 1.0648 | R8: 1.6943 | S8: 0.4346 | T8: 1.0619 | U8: 1.0278 | V8: 1.2976 | W8: 1.3811 | X8: 1.0099 | Y8: 1.2332 | Z8: 0.8249 | AA8: 1.0155 | AB8: 1.2773 | AC8: 1.9484 | AD8: 1.4161 | AE8: 0.6886 | AF8: 1.3168 | AG8: 1.9798 | AH8: 1.9367 | AI8: 1.0643 | AJ8: 1.2758 | CB8: 3.5455
A9: Coal production - Mine Level::Grosvenor | B9: VariousOperations_Calculations | C9: 17 | D9: Coal production - Mine Level | E9: Grosvenor | F9: Mt | G9: 100 | H9: MLCCI-1639775051-8792 | I9: Total production on 100% basis | V9: 0.0516 | W9: 0.1218 | X9: 0.1473 | Y9: 0.1791 | Z9: 0.203 | AA9: 0.3312 | AB9: 0.6857 | AC9: 0.5391 | AD9: 0.7098 | AE9: 0.1836 | AF9: 1.0125 | AG9: 0.1613 | AH9: 0.8256 | AI9: 1.342 | AJ9: 1.2398 | AK9: 0.3561 | CH9: 3.7635
A10: Coal production - Mine Level::Thermal -Export | B10: VariousOperations_Calculations | C10: 19 | D10: Coal production - Mine Level | E10: Thermal -Export | F10: Mt | M10: 1.6894 | N10: 1.4938 | O10: 1.5131 | P10: 1.6724 | Q10: 1.5847 | R10: 0.7693 | S10: 9.584 | T10: 1.5746 | U10: 1.8716 | V10: 1.4332 | W10: 1.3266 | X10: 1.3664 | Y10: 1.1543 | Z10: 1.0659 | AA10: 1.107 | AB10: 1.1127 | AC10: 0.6719
A11: Coal production - Mine Level::Thermal -Domestic | B11: VariousOperations_Calculations | C11: 20 | D11: Coal production - Mine Level | E11: Thermal -Domestic | F11: Mt | M11: 2.0253 | N11: 1.073 | O11: 1.7253 | P11: 1.7523 | Q11: 1.6888 | R11: 1.2279 | S11: 1.846 | T11: 2.0744 | U11: 1.9663 | V11: 1.6499 | W11: 1.6224 | X11: 1.8005 | Y11: 1.9788 | Z11: 1.4929 | AA11: 1.7167 | AB11: 1.682 | AC11: 0.6618
A12: Coal production - Mine Level::Total Thermal Export (Mine Level) | B12: VariousOperations_Calculations | C12: 21 | D12: Coal production - Mine Level | E12: Total Thermal Export (Mine Level) | F12: Mt | I12: Total Thermal coal production at attributable basis | J12: 2.5706 | K12: 3.2863 | L12: 3.3989 | AD12: 0.479 | AE12: 0.3047 | AF12: 0.4214 | AG12: 0.4086 | AH12: 0.2087 | AI12: 0.2899 | AJ12: 0.4551 | AK12: 0.4276 | AL12: 0.3385 | AM12: 0.2452 | AN12: 0.4379 | AO12: 0.3892 | AP12: 0.4032 | AQ12: 0.468 | AR12: 0.587 | AS12: 0.5623 | AT12: 0.3724 | AU12: 0.519 | AV12: 0.4438 | AW12: 0.3418 | AX12: 0.4274 | AY12: 0.3659 | AZ12: 0.424 | BA12: 0.4275 | BB12: 0.284 | BC12: 0.481 | BD12: 0.284 | BE12: 0.034 | BF12: 0.324 | BG12: 0.142 | BH12: 0.249 | BI12: 0.396 | BJ12: 0.244 | BK12: 0.298 | BL12: 0.269 | BM12: 0.413
A13: Coal production - Mine Level::Dawson | B13: VariousOperations_Calculations | C13: 24 | D13: Coal production - Mine Level | E13: Dawson | F13: Mt | CE13: 11.67297 | CF13: 12.040414 | CG13: 10.022541 | CH13: 9.35138 | CI13: 10.27 | CJ13: 9.508524
A14: Coal production - Mine Level::Lake Vermont | B14: VariousOperations_Calculations | C14: 25 | D14: Coal production - Mine Level | E14: Lake Vermont | F14: Mt | CE14: 11.084525 | CF14: 11.05623 | CG14: 10.828616 | CH14: 11.132 | CI14: 11.16 | CK14: 11.476069 | CL14: 10.948135 | CM14: 11.023168 | CN14: 10.840263
A15: Anglo's Share::Aquila | B15: VariousOperations_Calculations | C15: 33 | D15: Anglo's Share | E15: Aquila | F15: % | J15: 0.7 | K15: 0.7 | L15: 0.7 | M15: 0.7 | N15: 0.7 | O15: 0.7 | P15: 0.7 | Q15: 0.7 | R15: 0.7 | S15: 0.7 | T15: 0.7 | U15: 0.7 | V15: 0.7 | W15: 0.7 | X15: 0.7 | Y15: 0.7 | Z15: 0.7 | AA15: 0.7 | AB15: 0.7 | AC15: 0.7 | AD15: 0.7 | AE15: 0.7 | AF15: 0.7 | AG15: 0.7 | AH15: 0.7 | AI15: 0.7 | AJ15: 0.7 | AK15: 0.7 | AL15: 0.7 | AM15: 0.7 | AN15: 0.7 | AO15: 0.7 | AP15: 0.7 | AQ15: 0.7 | AR15: 0.7 | AS15: 0.7 | AT15: 0.7 | AU15: 0.7 | AV15: 0.7 | AW15: 0.7 | AX15: 0.7 | AY15: 0.7 | AZ15: 0.7 | BA15: 0.7 | BB15: 0.7 | BC15: 0.7 | BD15: 0.7 | BE15: 0.7 | BF15: 0.7 | BG15: 0.7 | BH15: 0.7 | BI15: 0.7 | BJ15: 0.7 | BK15: 0.7 | BL15: 0.7 | BM15: 0.7
A16: Anglo's Share::Callide | B16: VariousOperations_Calculations | C16: 34 | D16: Anglo's Share | E16: Callide | F16: % | J16: 1 | K16: 1 | L16: 1 | M16: 1 | N16: 1 | O16: 1 | P16: 1 | Q16: 1 | R16: 1 | S16: 1 | T16: 1 | U16: 1 | V16: 1 | W16: 1 | X16: 1 | Y16: 1 | Z16: 1 | AA16: 1 | AB16: 1 | AC16: 1
A17: Anglo's Share::Dawson | B17: VariousOperations_Calculations | C17: 35 | D17: Anglo's Share | E17: Dawson | F17: % | J17: 0.51 | K17: 0.51 | L17: 0.51 | M17: 0.51 | N17: 0.51 | O17: 0.51 | P17: 0.51 | Q17: 0.51 | R17: 0.51 | S17: 0.51 | T17: 0.51 | U17: 0.51 | V17: 0.51 | W17: 0.51 | X17: 0.51 | Y17: 0.51 | Z17: 0.51 | AA17: 0.51 | AB17: 0.51 | AC17: 0.51 | AD17: 0.51 | AE17: 0.51 | AF17: 0.51 | AG17: 0.51 | AH17: 0.51 | AI17: 0.51 | AJ17: 0.51 | AK17: 0.51 | AL17: 0.51 | AM17: 0.51 | AN17: 0.51 | AO17: 0.51 | AP17: 0.51 | AQ17: 0.51 | AR17: 0.51 | AS17: 0.51 | AT17: 0.51 | AU17: 0.51 | AV17: 0.51 | AW17: 0.51 | AX17: 0.51 | AY17: 0.51 | AZ17: 0.51 | BA17: 0.51 | BB17: 0.51 | BC17: 0.51 | BD17: 0.51 | BE17: 0.51 | BF17: 0.51 | BG17: 0.51 | BH17: 0.51 | BI17: 0.51 | BJ17: 0.51 | BK17: 0.51 | BL17: 0.51 | BM17: 0.51
A18: Anglo's Share::Drayton | B18: VariousOperations_Calculations | C18: 36 | D18: Anglo's Share | E18: Drayton | F18: % | J18: 0.882 | K18: 0.882 | L18: 0.882 | M18: 0.882 | N18: 0.882 | O18: 0.882 | P18: 0.882 | Q18: 0.882 | R18: 0.882 | S18: 0.882 | T18: 0.882 | U18: 0.882 | V18: 0.882 | W18: 0.882 | X18: 0.882 | Y18: 0.882 | Z18: 0.882 | AA18: 0.882 | AB18: 0.882 | AC18: 0.882
A19: Anglo's Share::Foxleigh | B19: VariousOperations_Calculations | C19: 37 | D19: Anglo's Share | E19: Foxleigh | F19: % | J19: 0.7 | K19: 0.7 | L19: 0.7 | M19: 0.7 | N19: 0.7 | O19: 0.7 | P19: 0.7 | Q19: 0.7 | R19: 0.7 | S19: 0.7 | T19: 0.7 | U19: 0.7 | V19: 0.7 | W19: 0.7 | X19: 0.7 | Y19: 0.7 | Z19: 0.7 | AA19: 0.7 | AB19: 0.7
A20: Anglo's Share::Grasstree | B20: VariousOperations_Calculations | C20: 38 | D20: Anglo's Share | E20: Grasstree | F20: % | J20: 0.7 | K20: 0.7 | L20: 0.7 | M20: 0.7 | N20: 0.7 | O20: 0.7 | P20: 0.7 | Q20: 0.7 | R20: 0.7 | S20: 0.7 | T20: 0.7 | U20: 0.7 | V20: 0.7 | W20: 0.7 | X20: 0.7 | Y20: 0.7 | Z20: 0.7 | AA20: 0.7 | AB20: 0.7 | AC20: 0.7 | AD20: 0.7 | AE20: 0.7 | AF20: 0.7 | AG20: 0.7 | AH20: 0.7 | AI20: 0.7 | AJ20: 0.7 | AK20: 0.7 | AL20: 0.7 | AM20: 0.7 | AN20: 0.7 | AO20: 0.7 | AP20: 0.7 | AQ20: 0.7 | AR20: 0.7 | AS20: 0.7 | AT20: 0.7 | AU20: 0.7 | AV20: 0.7 | AW20: 0.7 | AX20: 0.7
A21: Anglo's Share::Grosvenor | B21: VariousOperations_Calculations | C21: 39 | D21: Anglo's Share | E21: Grosvenor | F21: % | J21: 1 | K21: 1 | L21: 1 | M21: 1 | N21: 1 | O21: 1 | P21: 1 | Q21: 1 | R21: 1 | S21: 1 | T21: 1 | U21: 1 | V21: 1 | W21: 1 | X21: 1 | Y21: 1 | Z21: 1 | AA21: 1 | AB21: 1 | AC21: 1 | AD21: 1 | AE21: 1 | AF21: 1 | AG21: 1 | AH21: 1 | AI21: 1 | AJ21: 1 | AK21: 1 | AL21: 1 | AM21: 1 | AN21: 1 | AO21: 1 | AP21: 1 | AQ21: 1 | AR21: 1 | AS21: 0.88 | AT21: 0.88 | AU21: 0.88 | AV21: 0.88 | AW21: 0.88 | AX21: 0.88 | AY21: 0.88 | AZ21: 0.88 | BA21: 0.88 | BB21: 0.88 | BC21: 0.88 | BD21: 0.88 | BE21: 0.88 | BF21: 0.88 | BG21: 0.88 | BH21: 0.88 | BI21: 0.88
A22: Anglo's Share::Jellinbah East | B22: VariousOperations_Calculations | C22: 40 | D22: Anglo's Share | E22: Jellinbah East | F22: % | J22: 0.233 | K22: 0.233 | L22: 0.233 | M22: 0.233 | N22: 0.233 | O22: 0.233 | P22: 0.233 | Q22: 0.233 | R22: 0.233 | S22: 0.233 | T22: 0.233 | U22: 0.233 | V22: 0.233 | W22: 0.233 | X22: 0.233 | Y22: 0.233 | Z22: 0.233 | AA22: 0.233 | AB22: 0.233 | AC22: 0.233 | AD22: 0.233 | AE22: 0.233 | AF22: 0.233 | AG22: 0.233 | AH22: 0.233 | AI22: 0.233 | AJ22: 0.233 | AK22: 0.233 | AL22: 0.233 | AM22: 0.233 | AN22: 0.233 | AO22: 0.233 | AP22: 0.233 | AQ22: 0.233 | AR22: 0.233 | AS22: 0.233 | AT22: 0.233 | AU22: 0.233 | AV22: 0.233 | AW22: 0.233 | AX22: 0.233 | AY22: 0.233 | AZ22: 0.233 | BA22: 0.233 | BB22: 0.233 | BC22: 0.233 | BD22: 0.233 | BE22: 0.233 | BF22: 0.233 | BG22: 0.233 | BH22: 0.233 | BI22: 0.233
A23: Anglo's Share::Lake Lindsay | B23: VariousOperations_Calculations | C23: 41 | D23: Anglo's Share | E23: Lake Lindsay | F23: % | J23: 0.768 | K23: 0.768 | L23: 0.768 | M23: 0.768 | N23: 0.775 | O23: 0.775 | P23: 0.775 | Q23: 0.775 | R23: 0.775 | S23: 0.775 | T23: 0.775 | U23: 0.775 | V23: 0.776 | W23: 0.776 | X23: 0.776 | Y23: 0.776 | Z23: 0.783 | AA23: 0.783 | AB23: 0.783 | AC23: 0.783 | AD23: 0.786 | AE23: 0.786 | AF23: 0.786 | AG23: 0.786 | AH23: 0.779 | AI23: 0.779 | AJ23: 0.779 | AK23: 0.779 | AL23: 0.782 | AM23: 0.782 | AN23: 0.782 | AO23: 0.782 | AP23: 0.786 | AQ23: 0.786 | AR23: 0.786 | AS23: 0.786 | AT23: 0.792 | AU23: 0.792 | AV23: 0.792 | AW23: 0.792 | AX23: 0.792 | AY23: 0.792 | AZ23: 0.792 | BA23: 0.792 | BB23: 0.792 | BC23: 0.792 | BD23: 0.792 | BE23: 0.792 | BF23: 0.792 | BG23: 0.792 | BH23: 0.792 | BI23: 0.792 | BJ23: 0.792 | BK23: 0.792 | BL23: 0.792 | BM23: 0.792
A24: Anglo's Share::Lake Vermont | B24: VariousOperations_Calculations | C24: 42 | D24: Anglo's Share | E24: Lake Vermont | F24: % | J24: 0.233 | K24: 0.233 | L24: 0.233 | M24: 0.233 | N24: 0.233 | O24: 0.233 | P24: 0.233 | Q24: 0.233 | R24: 0.233 | S24: 0.233 | T24: 0.233 | U24: 0.233 | V24: 0.233 | W24: 0.233 | X24: 0.233 | Y24: 0.233 | Z24: 0.233 | AA24: 0.233 | AB24: 0.233 | AC24: 0.233 | AD24: 0.233 | AE24: 0.233 | AF24: 0.233 | AG24: 0.233 | AH24: 0.233 | AI24: 0.233 | AJ24: 0.233 | AK24: 0.233 | AL24: 0.233 | AM24: 0.233 | AN24: 0.233 | AO24: 0.233 | AP24: 0.233 | AQ24: 0.233 | AR24: 0.233 | AS24: 0.233 | AT24: 0.233 | AU24: 0.233 | AV24: 0.233 | AW24: 0.233 | AX24: 0.233 | AY24: 0.233 | AZ24: 0.233 | BA24: 0.233 | BB24: 0.233 | BC24: 0.233 | BD24: 0.233 | BE24: 0.233 | BF24: 0.233 | BG24: 0.233 | BH24: 0.233 | BI24: 0.233
A25: Anglo's Share::Moranbah North | B25: VariousOperations_Calculations | C25: 43 | D25: Anglo's Share | E25: Moranbah North | F25: % | J25: 0.88 | K25: 0.88 | L25: 0.88 | M25: 0.88 | N25: 0.88 | O25: 0.88 | P25: 0.88 | Q25: 0.88 | R25: 0.88 | S25: 0.88 | T25: 0.88 | U25: 0.88 | V25: 0.88 | W25: 0.88 | X25: 0.88 | Y25: 0.88 | Z25: 0.88 | AA25: 0.88 | AB25: 0.88 | AC25: 0.88 | AD25: 0.88 | AE25: 0.88 | AF25: 0.88 | AG25: 0.88 | AH25: 0.88 | AI25: 0.88 | AJ25: 0.88 | AK25: 0.88 | AL25: 0.88 | AM25: 0.88 | AN25: 0.88 | AO25: 0.88 | AP25: 0.88 | AQ25: 0.88 | AR25: 0.88 | AS25: 0.88 | AT25: 0.88 | AU25: 0.88 | AV25: 0.88 | AW25: 0.88 | AX25: 0.88 | AY25: 0.88 | AZ25: 0.88 | BA25: 0.88 | BB25: 0.88 | BC25: 0.88 | BD25: 0.88 | BE25: 0.88 | BF25: 0.88 | BG25: 0.88 | BH25: 0.88 | BI25: 0.88
A26: ROM Production::Dawson | B26: VariousOperations_Calculations | C26: 47 | D26: ROM Production | E26: Dawson | F26: Mt | H26: MLCCI-1066059444-48245; MLCCI-1066059444-54832; MLCCI-1066059444-62827; MLCCI-1639775051-122529; MLCCI-1639775051-130733; MLCCI-1639775051-92911; MLCCI-1639775051-92912 | I26: FY ROM production numbers; Calenderised ROM production based on FY numbers | BO26: 10.937099 | BP26: 11.604663 | BR26: 11.637862 | BS26: 12.075884 | BT26: 8.435228 | BU26: 9.530632 | BV26: 10.394706 | BW26: 9.16839 | BX26: 6.100998 | BY26: 9.146831 | BZ26: 8.765201 | CA26: 9.182172
A27: ROM Production::Moranbah North | B27: VariousOperations_Calculations | C27: 48 | D27: ROM Production | E27: Moranbah North | F27: Mt | H27: MLCCI-1066059444-48245; MLCCI-1066059444-54832; MLCCI-1066059444-62827; MLCCI-1639775051-122529; MLCCI-1639775051-130733; MLCCI-1639775051-92911; MLCCI-1639775051-92912 | I27: FY ROM production numbers; Calenderised ROM production based on FY numbers | BO27: 6.170481 | BP27: 6.461812 | BR27: 5.97881 | BS27: 7.733815 | BT27: 9.370519 | BU27: 7.476115 | BV27: 7.607259 | BW27: 5.768771 | BX27: 3.643425 | BY27: 6.196556 | BZ27: 4.809805 | CA27: 3.315001
A28: ROM Production::Foxleigh | B28: VariousOperations_Calculations | C28: 49 | D28: ROM Production | E28: Foxleigh | F28: Mt | H28: MLCCI-1639775051-92911; MLCCI-1639775051-92912 | I28: FY ROM production numbers; Calenderised ROM production based on FY numbers | BO28: 3.603434 | BP28: 1.854072 | BR28: 6.561215 | BS28: 4.891439
A29: ROM Production::Callide & Boundary Hill | B29: VariousOperations_Calculations | C29: 50 | D29: ROM Production | E29: Callide & Boundary Hill | F29: Mt | H29: MLCCI-1639775051-92911; MLCCI-1639775051-92912 | I29: FY ROM production numbers; Calenderised ROM production based on FY numbers | BO29: 6.842158 | BP29: 5.876718 | BR29: 7.838764 | BS29: 8.394299
A30: ROM Production::German Creek East | B30: VariousOperations_Calculations | C30: 51 | D30: ROM Production | E30: German Creek East | F30: Mt | H30: MLCCI-1639775051-92911 | I30: FY ROM production numbers; Calenderised ROM production based on FY numbers | BO30: 1.918171 | BP30: 1.114108
A31: ROM Production::German Creek - Lake Lindsay | B31: VariousOperations_Calculations | C31: 52 | D31: ROM Production | E31: German Creek - Lake Lindsay | F31: Mt | H31: MLCCI-1066059444-48245; MLCCI-1066059444-54832; MLCCI-1066059444-62827; MLCCI-1639775051-122529; MLCCI-1639775051-130733; MLCCI-1639775051-92911; MLCCI-1639775051-92912 | I31: FY ROM production numbers; Calenderised ROM production based on FY numbers | BO31: 5.303941 | BP31: 5.787516 | BR31: 5.673393 | BS31: 4.097363 | BT31: 3.886108 | BU31: 4.561048 | BV31: 5.385038 | BW31: 3.635346 | BX31: 3.456844 | BY31: 4127437 | BZ31: 3.853184 | CA31: 4.875968
A32: ROM Production::German Creek - Aquila | B32: VariousOperations_Calculations | C32: 53 | D32: ROM Production | E32: German Creek - Aquila | F32: Mt | H32: MLCCI-1639775051-92911 | I32: FY ROM production numbers; Calenderised ROM production based on FY numbers | BO32: 0.408779 | BP32: 0.248011 | BZ32: 5.433895 | CA32: 5.264619
A33: ROM Production::German Creek - Grasstree | B33: VariousOperations_Calculations | C33: 54 | D33: ROM Production | E33: German Creek - Grasstree | F33: Mt | H33: MLCCI-1066059444-54832; MLCCI-1066059444-62827; MLCCI-1639775051-122529; MLCCI-1639775051-130733; MLCCI-1639775051-92911; MLCCI-1639775051-92912 | I33: FY ROM production numbers; Calenderised ROM production based on FY numbers | BO33: 4.050885 | BP33: 6.126471 | BR33: 9.810094 | BS33: 7.276002 | BT33: 7.732954 | BU33: 6.930631 | BV33: 5.744934 | BW33: 6.911569 | BX33: 5.947984
A34: ROM Production::Jellinbah East | B34: VariousOperations_Calculations | C34: 55 | D34: ROM Production | E34: Jellinbah East | F34: Mt | H34: MLCCI-1066059444-48245; MLCCI-1066059444-54832; MLCCI-1066059444-62827; MLCCI-1639775051-122529; MLCCI-1639775051-130733; MLCCI-1639775051-92911; MLCCI-1639775051-92912 | I34: FY ROM production numbers; Calenderised ROM production based on FY numbers | BO34: 5.168184 | BP34: 5.466143 | BR34: 5.578113 | BS34: 5.27645 | BT34: 5.235631 | BU34: 4.69261 | BV34: 4.722276 | BW34: 5.59341 | BX34: 4.963446 | BY34: 4.724069 | BZ34: 6.125257 | CA34: 6.672883
A35: ROM Production::Lake Vermont | B35: VariousOperations_Calculations | C35: 56 | D35: ROM Production | E35: Lake Vermont | F35: Mt | H35: MLCCI-1066059444-48245; MLCCI-1066059444-54832; MLCCI-1066059444-62827; MLCCI-1639775051-122529; MLCCI-1639775051-130733; MLCCI-1639775051-92911; MLCCI-1639775051-92912 | I35: FY ROM production numbers; Calenderised ROM production based on FY numbers | BO35: 5.835788 | BP35: 9.227694 | BR35: 11.249826 | BS35: 10.775935 | BT35: 11.549 | BU35: 10.468 | BV35: 8.229006 | BW35: 9.466726 | BX35: 11.159508 | BY35: 10.647909 | BZ35: 11.198868 | CA35: 10.549505
A36: ROM Production::Grosvenor | B36: VariousOperations_Calculations | C36: 57 | D36: ROM Production | E36: Grosvenor | F36: Mt | H36: MLCCI-1066059444-48245; MLCCI-1066059444-54832; MLCCI-1066059444-62827; MLCCI-1639775051-122529; MLCCI-1639775051-130733; MLCCI-1639775051-92912 | BR36: 1.328956 | BS36: 3.689123 | BT36: 5.713199 | BU36: 6.090132 | BV36: 5.59616 | BW36: 4969 | BX36: 1.633762 | BY36: 5.705807 | BZ36: 6.666395 | CA36: 0.33033
A37: Total FY Saleable Production (Met + Thermal)::Dawson | B37: VariousOperations_Calculations | C37: 60 | D37: Total FY Saleable Production (Met + Thermal) | E37: Dawson | F37: Mt | H37: MLCCI-1639775051-111992; MLCCI-1639775051-92912; MLCCI-1639775051-93685; MLCCI-1639775051-96255 | BN37: 9.302882 | BQ37: 8.148072
A38: Total FY Saleable Production (Met + Thermal)::Jellinbah East | B38: VariousOperations_Calculations | C38: 61 | D38: Total FY Saleable Production (Met + Thermal) | E38: Jellinbah East | F38: Mt | H38: MLCCI-1639775051-111992; MLCCI-1639775051-92912; MLCCI-1639775051-93685; MLCCI-1639775051-96255 | BN38: 4.549875 | BQ38: 4.532332
A39: Total FY Saleable Production (Met + Thermal)::Lake Vermont | B39: VariousOperations_Calculations | C39: 62 | D39: Total FY Saleable Production (Met + Thermal) | E39: Lake Vermont | F39: Mt | H39: MLCCI-1639775051-111992; MLCCI-1639775051-92912; MLCCI-1639775051-93685; MLCCI-1639775051-96255 | BN39: 3.84558 | BQ39: 8.338484
A40: Total FY Saleable Production (Met + Thermal)::German Creek - Lake Lindsay | B40: VariousOperations_Calculations | C40: 63 | D40: Total FY Saleable Production (Met + Thermal) | E40: German Creek - Lake Lindsay | F40: Mt | H40: MLCCI-1639775051-111992; MLCCI-1639775051-92912; MLCCI-1639775051-93685; MLCCI-1639775051-96255 | BN40: 2.895436 | BQ40: 4.80146
...

Sheet VariousOperations_Calculations
A1: Anglo American Coal - Various Operations
A3: Color Legend
A4: Sourced datapoint
A5: Calculation
A6: Assumption | D6: Quarterly Production
D7: 2012 | E7: 2012 | F7: 2012 | G7: 2012 | H7: 2013 | I7: 2013 | J7: 2013 | K7: 2013 | L7: 2014 | M7: 2014 | N7: 2014 | O7: 2014 | P7: 2015 | Q7: 2015 | R7: 2015 | S7: 2015 | T7: 2016 | U7: 2016 | V7: 2016 | W7: 2016 | X7: 2017 | Y7: 2017 | Z7: 2017 | AA7: 2017 | AB7: 2018 | AC7: 2018 | AD7: 2018 | AE7: 2018 | AF7: 2019 | AG7: 2019 | AH7: 2019 | AI7: 2019 | AJ7: 2020 | AK7: 2020 | AL7: 2020 | AM7: 2020 | AN7: 2021 | AO7: 2021 | AP7: 2021 | AQ7: 2021 | AR7: 2022 | AS7: 2022 | AT7: 2022 | AU7: 2022 | AV7: 2023 | AW7: 2023 | AX7: 2023 | AY7: 2023 | AZ7: 2024 | BA7: 2024 | BB7: 2024 | BC7: 2024 | BD7: 2025 | BE7: 2025 | BF7: 2025 | BG7: 2025 | BX7: CY Production (100%) | CE7: CY Production (100%) | CU7: Source | CW7: Source
B8: Unit | C8: Anglo's Share (%) | D8: Q1 | E8: Q2 | F8: Q3 | G8: Q4 | H8: Q1 | I8: Q2 | J8: Q3 | K8: Q4 | L8: Q1 | M8: Q2 | N8: Q3 | O8: Q4 | P8: Q1 | Q8: Q1 | R8: Q3 | S8: Q4 | T8: Q1 | U8: Q2 | V8: Q3 | W8: Q4 | X8: Q1 | Y8: Q2 | Z8: Q3 | AA8: Q4 | AB8: Q1 | AC8: Q2 | AD8: Q3 | AE8: Q4 | AF8: Q1 | AG8: Q2 | AH8: Q3 | AI8: Q4 | AJ8: Q1 | AK8: Q2 | AL8: Q3 | AM8: Q4 | AN8: Q1 | AO8: Q2 | AP8: Q3 | AQ8: Q4 | AR8: Q1 | AS8: Q2 | AT8: Q3 | AU8: Q4 | AV8: Q1 | AW8: Q2 | AX8: Q3 | AY8: Q4 | AZ8: Q1 | BA8: Q2 | BB8: Q3 | BC8: Q4 | BD8: Q1 | BE8: Q2 | BF8: Q3 | BG8: Q4 | BI8: FY2012 2011-2012 | BJ8: FY2013 2012-2013 | BK8: FY2014 2013-2014 | BL8: FY2015 2014-2015 | BM8: FY2016 2015-2016 | BN8: FY2017 2016-2017 | BO8: FY2018 2017-2018 | BP8: FY2019 2018-2019 | BQ8: FY2020 2019-2020 | BR8: FY2021 2020-2021 | BS8: FY2022 2021-2022 | BT8: FY2023 2022-2023 | BU8: FY2024 2023-2024 | BV8: FY2025 2024-2025 | BX8: 2012 | BY8: 2013 | BZ8: 2014 | CA8: 2015 | CB8: 2016 | CC8: 2017 | CE8: 2012 | CF8: 2013 | CG8: 2014 | CH8: 2015 | CI8: 2016 | CJ8: 2017 | CK8: 2018 | CL8: 2019 | CM8: 2020 | CN8: 2021 | CO8: 2022 | CP8: 2023 | CQ8: 2024 | CS8: Comment/Description | CU8: Anglo Share(%) | CW8: FY2012 2011-2012 | CX8: FY2013 2012-2013 | CY8: FY2014 2013-2014 | CZ8: FY2015 2014-2015 | DA8: FY2016 2015-2016 | DB8: FY2017 2016-2017 | DC8: FY2018 2017-2018 | DD8: FY2019 2018-2019 | DE8: FY2020 2019-2020 | DF8: FY2021 2020-2021 | DG8: FY2022 2021-2022 | DH8: FY2023 2022-2023 | DI8: FY2024 2023-2024 | DJ8: FY2025 2024-2025 | DL8: Capacity | DM8: 2012 Q1 | DN8: 2012 Q2 | DO8: 2012 Q3 | DP8: 2012 Q4 | DQ8: 2013 Q1 | DR8: 2013 Q2 | DS8: 2013 Q3 | DT8: 2013 Q4 | DU8: 2014 Q1 | DV8: 2014 Q2 | DW8: 2014 Q3 | DX8: 2014 Q4 | DY8: 2015 Q1 | DZ8: 2015 Q2 | EA8: 2015 Q3 | EB8: 2015 Q4 | EC8: 2016 Q1 | ED8: 2016 Q2 | EE8: 2016 Q3 | EF8: 2016 Q4 | EG8: 2017 Q1 | EH8: 2017 Q2 | EI8: 2017 Q3 | EJ8: 2017 Q4 | EK8: 2018 Q1 | EL8: 2018 Q2 | EM8: 2018 Q3 | EN8: 2018 Q4 | EO8: 2019 Q1 | EP8: 2019 Q2 | EQ8: 2019 Q3 | ER8: 2019 Q4 | ES8: 2020 Q1 | ET8: 2020 Q2 | EU8: 2020 Q3 | EV8: 2020 Q4 | EW8: 2021 Q1 | EX8: 2021 Q2 | EY8: 2021 Q3 | EZ8: 2021 Q4 | FA8: 2022 Q1 | FB8: 2022 Q2 | FC8: 2022 Q3 | FD8: 2022 Q4 | FE8: 2023 Q1 | FF8: 2023 Q2 | FG8: 2023 Q3 | FH8: 2023 Q4 | FI8: 2024 Q1 | FJ8: 2024 Q2 | FK8: 2024 Q3 | FL8: 2024 Q4 | FN8: 2012 | FO8: 2013 | FP8: 2014 | FQ8: 2015 | FR8: 2016 | FS8: 2017 | FT8: 2018 | FU8: 2019 | FV8: 2020 | FW8: 2021 | FX8: 2022 | FY8: 2023 | FZ8: 2024
A9: Coal production - Mine Level
A10: Callide | B10: Mt | C10: 100 | H10: =SourcedData!N2/$C$10% -> 1.1514 | I10: =SourcedData!O2/$C$10% -> 1.7253 | J10: =SourcedData!P2/$C$10% -> 1.7523 | K10: =SourcedData!Q2/$C$10% -> 1.6888 | L10: =SourcedData!R2/$C$10% -> 1.2292 | M10: =SourcedData!S2/$C$10% -> 1.8446 | N10: =SourcedData!T2/$C$10% -> 2.3185 | O10: =SourcedData!U2/$C$10% -> 2.1647 | ... W10: =SourcedData!AC2/$C$10% -> 0.7384 | BX10: =SourcedData!CB2 -> 7.464 | CE10: =BX10/C10% -> 7.464 | CF10: =SUMIF($H$7:$AA$7,CF$8,$H10:$AA10) -> 6.3178 | CG10: =SUMIF($H$7:$AA$7,CG$8,$H10:$AA10) -> 7.557 | CH10: =SUMIF($H$7:$AA$7,CH$8,$H10:$AA10) -> 7.9304 | CI10: =SUMIF($H$7:$AA$7,CI$8,$H10:$AA10) -> 6.2308 | CS10: Total production on 100% basis. Sold end of 2016 | CU10: MLCCI-1639775051-8792 | DQ10: MLCCI-6-1114 | DR10: MLCCI-6-1114 | DS10: MLCCI-6-1114 | DT10: MLCCI-6-1114 | DU10: MLCCI-1639775051-92906 | DV10: MLCCI-1639775051-92906 | DW10: MLCCI-1639775051-92906 | DX10: MLCCI-1639775051-92906 | DY10: MLCCI-991351766-5109 | DZ10: MLCCI-991351766-5109 | EA10: MLCCI-991351766-5109 | EB10: MLCCI-991351766-5109 | EC10: MLCCI-1639775051-23485 | ED10: MLCCI-1639775051-23485 | EE10: MLCCI-1639775051-23485 | EF10: MLCCI-1639775051-23485 | FN10: MLCCI-6-1112
A11: Capcoal (Grasstree, Lake Lindsay and Aquila mines) | B11: Mt | C11: 70 | H11: =SourcedData!N3/$C$11% -> 2.0221429 | I11: =SourcedData!O3/$C$11% -> 2.0872857 | J11: =SourcedData!P3/$C$11% -> 2.2942857 | K11: =SourcedData!Q3/$C$11% -> 2.2554286 | L11: =SourcedData!R3/$C$11% -> 2.721 | M11: =SourcedData!S3/$C$11% -> 2.6392857 | N11: =SourcedData!T3/$C$11% -> 2.5947143 | O11: =SourcedData!U3/$C$11% -> 2.9632857 | ... W11: =SourcedData!AC3/$C$11% -> 1.7574286 | X11: =X93+X115 -> 2.437297 | Y11: =Y93+Y115 -> 2.0626629 | Z11: =Z93+Z115 -> 2.4239043 | AA11: =AA93+AA115 -> 2.3195686 | AB11: =AB93+AB115 -> 1.9979494 | AC11: =AC93+AC115 -> 1.900156 | AD11: =AD93+AD115 -> 2.2370618 | AE11: =AE93+AE115 -> 1.9654759 | ... BC11: =BC93+BC115 -> 1.573765 | BX11: =SourcedData!CB3 -> 6.0224 | CE11: =BX11/C11% -> 8.6034286 | CF11: =SUMIF($H$7:$AA$7,CF$8,$H11:$AA11) -> 8.6591429 | CG11: =SUMIF($H$7:$AA$7,CG$8,$H11:$AA11) -> 10.918286 | CH11: =SUMIF($H$7:$AA$7,CH$8,$H11:$AA11) -> 12.413857 | CI11: =SUMIF($H$7:$AA$7,CI$8,$H11:$AA11) -> 9.7612857 | CJ11: =SUMIF($D$7:$BH$7,CJ$8,$D11:$BH11) -> 9.2434328 | CK11: =SUMIF($D$7:$BH$7,CK$8,$D11:$BH11) -> 8.1006431 | CL11: =SUMIF($D$7:$BH$7,CL$8,$D11:$BH11) -> 8.4796258 | CM11: =SUMIF($D$7:$BH$7,CM$8,$D11:$BH11) -> 8.1788883 | CN11: =SUMIF($D$7:$BH$7,CN$8,$D11:$BH11) -> 8.5998838 | CO11: =SUMIF($D$7:$BH$7,CO$8,$D11:$BH11) -> 5.0565008 | CP11: =SUMIF($D$7:$BH$7,CP$8,$D11:$BH11) -> 5.9597806 | CQ11: =SUMIF($D$7:$BH$7,CQ$8,$D11:$BH11) -> 5.4541357 | CS11: Total production on 100% basis; calculated using attributable production and % stake of the company in mine; Calculated using sum of quarterly figures except for 2012; For 2012 calendar year is considered and calculated using attributable production and % stake of the company in mine | CU11: MLCCI-6-1112 | DQ11: MLCCI-6-1114 | DR11: MLCCI-6-1114 | DS11: MLCCI-6-1114 | DT11: MLCCI-6-1114 | DU11: MLCCI-1639775051-92906 | DV11: MLCCI-1639775051-92906 | DW11: MLCCI-1639775051-92906 | DX11: MLCCI-1639775051-92906 | DY11: MLCCI-991351766-5109 | DZ11: MLCCI-991351766-5109 | EA11: MLCCI-991351766-5109 | EB11: MLCCI-991351766-5109 | EC11: MLCCI-1639775051-23485 | ED11: MLCCI-1639775051-23485 | EE11: MLCCI-1639775051-23485 | EF11: MLCCI-1639775051-23485 | EG11: MLCCI-1639775051-83982 | EH11: MLCCI-1639775051-83982 | EI11: MLCCI-1639775051-83982 | EJ11: MLCCI-1639775051-83982 | EK11: MLCCI-1639775051-95005 | EL11: MLCCI-1639775051-95005 | EM11: MLCCI-1639775051-95005 | EN11: MLCCI-1639775051-95005 | EO11: MLCCI-1639775051-105346 | EP11: MLCCI-1639775051-105346 | EQ11: MLCCI-1639775051-105346 | ER11: MLCCI-1639775051-105346 | FN11: MLCCI-6-1112
A12: Dawson | B12: Mt | C12: 51 | H12: =SourcedData!N4/$C$12% -> 1.4756863 | I12: =SourcedData!O4/$C$12% -> 2.1119608 | J12: =SourcedData!P4/$C$12% -> 1.9476471 | K12: =SourcedData!Q4/$C$12% -> 2.2798039 | L12: =SourcedData!R4/$C$12% -> 2.0054902 | M12: =SourcedData!S4/$C$12% -> 2.1592157 | N12: =SourcedData!T4/$C$12% -> 2.0419608 | O12: =SourcedData!U4/$C$12% -> 2.107451 | ... AA12: =SourcedData!AG4/$C$12% -> 1.2362745 | AB12: =AB86+AB113 -> 1.272549 | AC12: =AC86+AC113 -> 1.7794118 | AD12: =AD86+AD113 -> 1.64 | AE12: =AE86+AE113 -> 1.9345098 | AF12: =AF86+AF113 -> 1.7580392 | AG12: =AG86+AG113 -> 1.8023529 | AH12: =AH86+AH113 -> 2.012549 | AI12: =AI86+AI113 -> 2.0890196 | ... BC12: =BC86+BC113 -> 2.1568627 | BX12: =SourcedData!CB4 -> 4.5935 | CE12: =BX12/C12% -> 9.0068627 | CF12: =SUMIF($H$7:$AA$7,CF$8,$H12:$AA12) -> 7.815098 | CG12: =SUMIF($H$7:$AA$7,CG$8,$H12:$AA12) -> 8.3141176 | CH12: =SUMIF($H$7:$AA$7,CH$8,$H12:$AA12) -> 8.4598039 | CI12: =SUMIF($H$7:$AA$7,CI$8,$H12:$AA12) -> 9.0366667 | CJ12: =SUMIF($D$7:$BH$7,CJ$8,$D12:$BH12) -> 7.4160784 | CK12: =SUMIF($D$7:$BH$7,CK$8,$D12:$BH12) -> 6.6264706 | CL12: =SUMIF($D$7:$BH$7,CL$8,$D12:$BH12) -> 7.6619608 | CM12: =SUMIF($D$7:$BH$7,CM$8,$D12:$BH12) -> 7.4780392 | CN12: =SUMIF($D$7:$BH$7,CN$8,$D12:$BH12) -> 6.9169731 | CO12: =SUMIF($D$7:$BH$7,CO$8,$D12:$BH12) -> 6.1927451 | CP12: =SUMIF($D$7:$BH$7,CP$8,$D12:$BH12) -> 7.0401961 | CQ12: =SUMIF($D$7:$BH$7,CQ$8,$D12:$BH12) -> 6.9 | CS12: Total production on 100% basis; calculated using attributable production and % stake of the company in mine; Calculated using sum of quarterly figures except for 2012; For 2012 calendar year is considered and calculated using attributable production and % stake of the company in mine | CU12: MLCCI-6-1112 | DQ12: MLCCI-6-1114 | DR12: MLCCI-6-1114 | DS12: MLCCI-6-1114 | DT12: MLCCI-6-1114 | DU12: MLCCI-1639775051-92906 | DV12: MLCCI-1639775051-92906 | DW12: MLCCI-1639775051-92906 | DX12: MLCCI-1639775051-92906 | DY12: MLCCI-991351766-5109 | DZ12: MLCCI-991351766-5109 | EA12: MLCCI-991351766-5109 | EB12: MLCCI-991351766-5109 | EC12: MLCCI-1639775051-23485 | ED12: MLCCI-1639775051-23485 | EE12: MLCCI-1639775051-23485 | EF12: MLCCI-1639775051-23485 | EG12: MLCCI-1639775051-83982 | EH12: MLCCI-1639775051-83982 | EI12: MLCCI-1639775051-83982 | EJ12: MLCCI-1639775051-83982 | EK12: MLCCI-1639775051-95005 | EL12: MLCCI-1639775051-95005 | EM12: MLCCI-1639775051-95005 | EN12: MLCCI-1639775051-95005 | EO12: MLCCI-1639775051-105346 | EP12: MLCCI-1639775051-105346 | EQ12: MLCCI-1639775051-105346 | ER12: MLCCI-1639775051-105346 | FN12: MLCCI-6-1112
A13: Drayton | B13: Mt | C13: 88 | H13: =SourcedData!N5/$C$13% -> 1.0152273 | I13: =SourcedData!O5/$C$13% -> 0.89204545 | J13: =SourcedData!P5/$C$13% -> 1.1998864 | K13: =SourcedData!Q5/$C$13% -> 1.1095455 | L13: =SourcedData!R5/$C$13% -> 0.74897727 | M13: =SourcedData!S5/$C$13% -> 0.80511364 | N13: =SourcedData!T5/$C$13% -> 0.92840909 | O13: =SourcedData!U5/$C$13% -> 1.0456818 | ... W13: =SourcedData!AC5/$C$13% -> 0.093522727 | BX13: =SourcedData!CB5 -> 3.6633 | CE13: =BX13/C13% -> 4.1628409 | CF13: =SUMIF($H$7:$AA$7,CF$8,$H13:$AA13) -> 4.2167045 | CG13: =SUMIF($H$7:$AA$7,CG$8,$H13:$AA13) -> 3.5281818 | CH13: =SUMIF($H$7:$AA$7,CH$8,$H13:$AA13) -> 2.4113636 | CI13: =SUMIF($H$7:$AA$7,CI$8,$H13:$AA13) -> 1.3267045 | CS13: Total production on 100% basis; calculated using attributable production and % stake of the company in mine; Calculated using sum of quarterly figures except for 2012; For 2012 calendar year is considered and calculated using attributable production and % stake of the company in mine; Ceased mining activities at the Drayton mine in 2016. | CU13: MLCCI-6-1112 | DQ13: MLCCI-6-1114 | DR13: MLCCI-6-1114 | DS13: MLCCI-6-1114 | DT13: MLCCI-6-1114 | DU13: MLCCI-1639775051-92906 | DV13: MLCCI-1639775051-92906 | DW13: MLCCI-1639775051-92906 | DX13: MLCCI-1639775051-92906 | DY13: MLCCI-991351766-5109 | DZ13: MLCCI-991351766-5109 | EA13: MLCCI-991351766-5109 | EB13: MLCCI-991351766-5109 | EC13: MLCCI-1639775051-23485 | ED13: MLCCI-1639775051-23485 | EE13: MLCCI-1639775051-23485 | EF13: MLCCI-1639775051-23485 | FN13: MLCCI-6-1112
A14: Foxleigh | B14: Mt | C14: 70 | H14: =SourcedData!N6/$C$14% -> 0.75428571 | I14: =SourcedData!O6/$C$14% -> 0.67957143 | J14: =SourcedData!P6/$C$14% -> 0.77285714 | K14: =SourcedData!Q6/$C$14% -> 0.60271429 | L14: =SourcedData!R6/$C$14% -> 0.61842857 | M14: =SourcedData!S6/$C$14% -> 0.67314286 | N14: =SourcedData!T6/$C$14% -> 0.78742857 | O14: =SourcedData!U6/$C$14% -> 0.82742857 | ... V14: =SourcedData!AB6/$C$14% -> 0.627 | BX14: =SourcedData!CB6 -> 1.896 | CE14: =BX14/C14% -> 2.7085714 | CF14: =SUMIF($H$7:$AA$7,CF$8,$H14:$AA14) -> 2.8094286 | CG14: =SUMIF($H$7:$AA$7,CG$8,$H14:$AA14) -> 2.9064286 | CH14: =SUMIF($H$7:$AA$7,CH$8,$H14:$AA14) -> 2.658 | CS14: Total production on 100% basis; calculated using attributable production and % stake of the company in mine; Calculated using sum of quarterly figures except for 2012; For 2012 calendar year is considered and calculated using attributable production and % stake of the company in mine. SOld end of 2016 | CU14: MLCCI-1639775051-8792 | DQ14: MLCCI-6-1114 | DR14: MLCCI-6-1114 | DS14: MLCCI-6-1114 | DT14: MLCCI-6-1114 | DU14: MLCCI-1639775051-92906 | DV14: MLCCI-1639775051-92906 | DW14: MLCCI-1639775051-92906 | DX14: MLCCI-1639775051-92906 | DY14: MLCCI-991351766-5109 | DZ14: MLCCI-991351766-5109 | EA14: MLCCI-991351766-5109 | EB14: MLCCI-991351766-5109 | EC14: MLCCI-1639775051-23485 | ED14: MLCCI-1639775051-23485 | EE14: MLCCI-1639775051-23485 | FN14: MLCCI-6-1112
A15: Jellinbah Group (Lake Vermont and Jellinbah East) | B15: Mt | C15: 23.3 | H15: =SourcedData!N7/$C$15% -> 2.0480687 | I15: =SourcedData!O7/$C$15% -> 2.6180258 | J15: =SourcedData!P7/$C$15% -> 2.8901288 | K15: =SourcedData!Q7/$C$15% -> 3.244206 | L15: =SourcedData!R7/$C$15% -> 2.9077253 | M15: =SourcedData!S7/$C$15% -> 3.2459227 | N15: =SourcedData!T7/$C$15% -> 3.1450644 | O15: =SourcedData!U7/$C$15% -> 3.2493562 | ... AA15: =SourcedData!AG7/$C$15% -> 3.6935622 | AB15: =AB97+AB118 -> 3.7553648 | AC15: =AC97+AC118 -> 3.6386266 | AD15: =AD97+AD118 -> 3.644206 | AE15: =AE97+AE118 -> 3.4678112 | AF15: =AF97+AF118 -> 3.2094421 | AG15: =AG97+AG118 -> 3.1381974 | AH15: =AH97+AH118 -> 3.7437768 | AI15: =AI97+AI118 -> 3.7321888 | ... BC15: =BC97+BC118 -> 1.5675966 | BX15: =SourcedData!CB7 -> 2.0732 | CE15: =BX15/C15% -> 8.8978541 | CF15: =SUMIF($H$7:$AA$7,CF$8,$H15:$AA15) -> 10.800429 | CG15: =SUMIF($H$7:$AA$7,CG$8,$H15:$AA15) -> 12.548069 | CH15: =SUMIF($H$7:$AA$7,CH$8,$H15:$AA15) -> 13.739914 | CI15: =SUMIF($H$7:$AA$7,CI$8,$H15:$AA15) -> 14.087124 | CJ15: =SUMIF($D$7:$BH$7,CJ$8,$D15:$BH15) -> 13.972532 | CK15: =SUMIF($D$7:$BH$7,CK$8,$D15:$BH15) -> 14.506009 | CL15: =SUMIF($D$7:$BH$7,CL$8,$D15:$BH15) -> 13.823605 | CM15: =SUMIF($D$7:$BH$7,CM$8,$D15:$BH15) -> 14.753129 | CN15: =SUMIF($D$7:$BH$7,CN$8,$D15:$BH15) -> 14.471926 | CO15: =SUMIF($D$7:$BH$7,CO$8,$D15:$BH15) -> 14.206223 | CP15: =SUMIF($D$7:$BH$7,CP$8,$D15:$BH15) -> 13.962876 | CQ15: =SUMIF($D$7:$BH$7,CQ$8,$D15:$BH15) -> 12.67382 | CS15: Total production on 100% basis; calculated using attributable production and % stake of the company in mine; Calculated using sum of quarterly figures except for 2012; For 2012 calendar year is considered and calculated using attributable production and % stake of the company in mine | CU15: MLCCI-6-1112 | DQ15: MLCCI-6-1114 | DR15: MLCCI-6-1114 | DS15: MLCCI-6-1114 | DT15: MLCCI-6-1114 | DU15: MLCCI-1639775051-92906 | DV15: MLCCI-1639775051-92906 | DW15: MLCCI-1639775051-92906 | DX15: MLCCI-1639775051-92906 | DY15: MLCCI-991351766-5109 | DZ15: MLCCI-991351766-5109 | EA15: MLCCI-991351766-5109 | EB15: MLCCI-991351766-5109 | EC15: MLCCI-1639775051-23485 | ED15: MLCCI-1639775051-23485 | EE15: MLCCI-1639775051-23485 | EF15: MLCCI-1639775051-23485 | EG15: MLCCI-1639775051-83982 | EH15: MLCCI-1639775051-83982 | EI15: MLCCI-1639775051-83982 | EJ15: MLCCI-1639775051-83982 | EK15: MLCCI-1639775051-95005 | EL15: MLCCI-1639775051-95005 | EM15: MLCCI-1639775051-95005 | EN15: MLCCI-1639775051-95005 | EO15: MLCCI-1639775051-105346 | EP15: MLCCI-1639775051-105346 | EQ15: MLCCI-1639775051-105346 | ER15: MLCCI-1639775051-105346 | FN15: MLCCI-6-1112
A16: Moranbah North | B16: Mt | C16: 88 | H16: =SourcedData!N8/$C$16% -> 1.7043182 | I16: =SourcedData!O8/$C$16% -> 1.1947727 | J16: =SourcedData!P8/$C$16% -> 1.4778409 | K16: =SourcedData!Q8/$C$16% -> 1.21 | L16: =SourcedData!R8/$C$16% -> 1.9253409 | M16: =SourcedData!S8/$C$16% -> 0.49386364 | N16: =SourcedData!T8/$C$16% -> 1.2067045 | O16: =SourcedData!U8/$C$16% -> 1.1679545 | ... AD16: =SourcedData!AJ8/$C$16% -> 1.4497727 | AE16: =AE87 -> 2.8240909 | AF16: =AF87 -> 0.27215909 | AG16: =AG87 -> 1.8218182 | AH16: =AH87 -> 2.2421591 | AI16: =AI87 -> 2.6506818 | AJ16: =AJ87 -> 0.51227273 | AK16: =AK87 -> 0.86568182 | AL16: =AL87 -> 2.2823864 | ... BC16: =BC87 -> 0.2 | BX16: =SourcedData!CB8 -> 3.5455 | CE16: =BX16/C16% -> 4.0289773 | CF16: =SUMIF($H$7:$AA$7,CF$8,$H16:$AA16) -> 5.5869318 | CG16: =SUMIF($H$7:$AA$7,CG$8,$H16:$AA16) -> 4.7938636 | CH16: =SUMIF($H$7:$AA$7,CH$8,$H16:$AA16) -> 5.5929545 | CI16: =SUMIF($H$7:$AA$7,CI$8,$H16:$AA16) -> 5.7569318 | CJ16: =SUMIF($D$7:$BH$7,CJ$8,$D16:$BH16) -> 6.1378409 | CK16: =SUMIF($D$7:$BH$7,CK$8,$D16:$BH16) -> 7.6840909 | CL16: =SUMIF($D$7:$BH$7,CL$8,$D16:$BH16) -> 6.9868182 | CM16: =SUMIF($D$7:$BH$7,CM$8,$D16:$BH16) -> 5.0344318 | CN16: =SUMIF($D$7:$BH$7,CN$8,$D16:$BH16) -> 3.4667045 | CO16: =SUMIF($D$7:$BH$7,CO$8,$D16:$BH16) -> 3.8572727 | CP16: =SUMIF($D$7:$BH$7,CP$8,$D16:$BH16) -> 3.5590909 | CQ16: =SUMIF($D$7:$BH$7,CQ$8,$D16:$BH16) -> 3.1556818 | CS16: Total production on 100% basis; calculated using attributable production and % stake of the company in mine; Calculated using sum of quarterly figures except for 2012; For 2012 calendar year is considered and calculated using attributable production and % stake of the company in mine | CU16: MLCCI-1639775051-8792 | DQ16: MLCCI-6-1114 | DR16: MLCCI-6-1114 | DS16: MLCCI-6-1114 | DT16: MLCCI-6-1114 | DU16: MLCCI-1639775051-92906 | DV16: MLCCI-1639775051-92906 | DW16: MLCCI-1639775051-92906 | DX16: MLCCI-1639775051-92906 | DY16: MLCCI-991351766-5109 | DZ16: MLCCI-991351766-5109 | EA16: MLCCI-991351766-5109 | EB16: MLCCI-991351766-5109 | EC16: MLCCI-1639775051-23485 | ED16: MLCCI-1639775051-23485 | EE16: MLCCI-1639775051-23485 | EF16: MLCCI-1639775051-23485 | EG16: MLCCI-1639775051-83982 | EH16: MLCCI-1639775051-83982 | EI16: MLCCI-1639775051-83982 | EJ16: MLCCI-1639775051-83982 | EK16: MLCCI-1639775051-95005 | EL16: MLCCI-1639775051-95005 | EM16: MLCCI-1639775051-95005 | EN16: MLCCI-1639775051-95005 | EO16: MLCCI-1639775051-105346 | EP16: MLCCI-1639775051-105346 | EQ16: MLCCI-1639775051-105346 | ER16: MLCCI-1639775051-105346 | FN16: MLCCI-6-1112
A17: Grosvenor | B17: Mt | C17: 100 | P17: =SourcedData!V9/$C$17% -> 0.0516 | Q17: =SourcedData!W9/$C$17% -> 0.1218 | R17: =SourcedData!X9/$C$17% -> 0.1473 | S17: =SourcedData!Y9/$C$17% -> 0.1791 | T17: =SourcedData!Z9/$C$17% -> 0.203 | U17: =SourcedData!AA9/$C$17% -> 0.3312 | V17: =SourcedData!AB9/$C$17% -> 0.6857 | W17: =SourcedData!AC9/$C$17% -> 0.5391 | ... AA17: =SourcedData!AG9/$C$17% -> 0.1613 | AB17: =SourcedData!AH9 -> 0.8256 | AC17: =SourcedData!AI9 -> 1.342 | AD17: =SourcedData!AJ9 -> 1.2398 | AE17: =SourcedData!AK9 -> 0.3561 | AF17: =AF94 -> 1.3332 | AG17: =AG94 -> 1.0325 | AH17: =AH94 -> 1.3445 | AI17: =AI94 -> 1.0117 | AJ17: =AJ94 -> 0.5409 | AK17: =AK94 -> 0.5609 | AL17: =AL94 -> 0.0045 | AM17: =AM94 -> 0 | ... BC17: =BC94 -> 0 | CH17: =SUMIF($H$7:$AA$7,CH$8,$H17:$AA17) -> 0.4998 | CI17: =SUMIF($H$7:$AA$7,CI$8,$H17:$AA17) -> 1.759 | CJ17: =SUMIF($D$7:$BH$7,CJ$8,$D17:$BH17) -> 2.0672 | CK17: =SourcedData!CH9 -> 3.7635 | CL17: =SUMIF($D$7:$BH$7,CL$8,$D17:$BH17) -> 4.7219 | CM17: =SUMIF($D$7:$BH$7,CM$8,$D17:$BH17) -> 1.1063 | CN17: =SUMIF($D$7:$BH$7,CN$8,$D17:$BH17) -> 0.081363636 | CO17: =SUMIF($D$7:$BH$7,CO$8,$D17:$BH17) -> 3.4505682 | CP17: =SUMIF($D$7:$BH$7,CP$8,$D17:$BH17) -> 3.1784091 | CQ17: =SUMIF($D$7:$BH$7,CQ$8,$D17:$BH17) -> 2.6965909 | CS17: Total production on 100% basis | CU17: MLCCI-1639775051-8792 | DY17: MLCCI-991351766-5109 | DZ17: MLCCI-991351766-5109 | EA17: MLCCI-991351766-5109 | EB17: MLCCI-991351766-5109 | EC17: MLCCI-1639775051-23485 | ED17: MLCCI-1639775051-23485 | EE17: MLCCI-1639775051-23485 | EF17: MLCCI-1639775051-23485 | EG17: MLCCI-1639775051-83982 | EH17: MLCCI-1639775051-83982 | EI17: MLCCI-1639775051-83982 | EJ17: MLCCI-1639775051-83982 | EK17: MLCCI-1639775051-95005 | EL17: MLCCI-1639775051-95005 | EM17: MLCCI-1639775051-95005 | EN17: MLCCI-1639775051-95005 | EO17: MLCCI-1639775051-105346 | EP17: MLCCI-1639775051-105346 | EQ17: MLCCI-1639775051-105346 | ER17: MLCCI-1639775051-105346 | FT17: MLCCI-1639775051-96148
A19: Thermal -Export | B19: Mt | G19: =SourcedData!M10 -> 1.6894 | H19: =SourcedData!N10 -> 1.4938 | I19: =SourcedData!O10 -> 1.5131 | J19: =SourcedData!P10 -> 1.6724 | K19: =SourcedData!Q10 -> 1.5847 | L19: =SourcedData!R10 -> 0.7693 | M19: =SourcedData!S10 -> 9.584 | N19: =SourcedData!T10 -> 1.5746 | ... W19: =SourcedData!AC10 -> 0.6719 | DQ19: MLCCI-6-1114 | DR19: MLCCI-6-1114 | DS19: MLCCI-6-1114 | DT19: MLCCI-6-1114 | DU19: MLCCI-1639775051-92906 | DV19: MLCCI-1639775051-92906 | DW19: MLCCI-1639775051-92906 | DX19: MLCCI-1639775051-92906 | DY19: MLCCI-991351766-5109 | DZ19: MLCCI-991351766-5109 | EA19: MLCCI-991351766-5109 | EB19: MLCCI-991351766-5109 | EC19: MLCCI-1639775051-23485 | ED19: MLCCI-1639775051-23485 | EE19: MLCCI-1639775051-23485 | EF19: MLCCI-1639775051-23485
A20: Thermal -Domestic | B20: Mt | G20: =SourcedData!M11 -> 2.0253 | H20: =SourcedData!N11 -> 1.073 | I20: =SourcedData!O11 -> 1.7253 | J20: =SourcedData!P11 -> 1.7523 | K20: =SourcedData!Q11 -> 1.6888 | L20: =SourcedData!R11 -> 1.2279 | M20: =SourcedData!S11 -> 1.846 | N20: =SourcedData!T11 -> 2.0744 | ... W20: =SourcedData!AC11 -> 0.6618 | DQ20: MLCCI-6-1114 | DR20: MLCCI-6-1114 | DS20: MLCCI-6-1114 | DT20: MLCCI-6-1114 | DU20: MLCCI-1639775051-92906 | DV20: MLCCI-1639775051-92906 | DW20: MLCCI-1639775051-92906 | DX20: MLCCI-1639775051-92906 | DY20: MLCCI-991351766-5109 | DZ20: MLCCI-991351766-5109 | EA20: MLCCI-991351766-5109 | EB20: MLCCI-991351766-5109 | EC20: MLCCI-1639775051-23485 | ED20: MLCCI-1639775051-23485 | EE20: MLCCI-1639775051-23485 | EF20: MLCCI-1639775051-23485
A21: Total Thermal Export (Mine Level) | B21: Mt | D21: =SourcedData!J12 -> 2.5706 | E21: =SourcedData!K12 -> 3.2863 | F21: =SourcedData!L12 -> 3.3989 | G21: =SUM(G19:G20) -> 3.7147 | H21: =SUM(H19:H20) -> 2.5668 | I21: =SUM(I19:I20) -> 3.2384 | J21: =SUM(J19:J20) -> 3.4247 | K21: =SUM(K19:K20) -> 3.2735 | L21: =SUM(L19:L20) -> 1.9972 | M21: =SUM(M19:M20) -> 11.43 | N21: =SUM(N19:N20) -> 3.649 | ... W21: =SUM(W19:W20) -> 1.3337 | X21: =SourcedData!AD12 -> 0.479 | Y21: =SourcedData!AE12 -> 0.3047 | Z21: =SourcedData!AF12 -> 0.4214 | AA21: =SourcedData!AG12 -> 0.4086 | AB21: =SourcedData!AH12 -> 0.2087 | AC21: =SourcedData!AI12 -> 0.2899 | AD21: =SourcedData!AJ12 -> 0.4551 | AE21: =SourcedData!AK12 -> 0.4276 | ... BG21: =SourcedData!BM12 -> 0.413 | CE21: =SUMIF($D$7:$AA$7,CE$8,$D21:$AA21) -> 12.9705 | CF21: =SUMIF($D$7:$AA$7,CF$8,$D21:$AA21) -> 12.5034 | CG21: =SUMIF($D$7:$AA$7,CG$8,$D21:$AA21) -> 20.9141 | CH21: =SUMIF($D$7:$AA$7,CH$8,$D21:$AA21) -> 12.3321 | CI21: =SUMIF($D$7:$AA$7,CI$8,$D21:$AA21) -> 9.5109 | CJ21: =SUMIF($D$7:$BH$7,CJ$8,$D21:$BH21) -> 1.6137 | CK21: =SUMIF($D$7:$BH$7,CK$8,$D21:$BH21) -> 1.3813 | CL21: =SUMIF($D$7:$BH$7,CL$8,$D21:$BH21) -> 1.4108 | CM21: =SUMIF($D$7:$BH$7,CM$8,$D21:$BH21) -> 2.0205 | CN21: =SUMIF($D$7:$BH$7,CN$8,$D21:$BH21) -> 1.677 | CO21: =SUMIF($D$7:$BH$7,CO$8,$D21:$BH21) -> 1.6448 | CP21: =SUMIF($D$7:$BH$7,CP$8,$D21:$BH21) -> 1.083 | CQ21: =SUMIF($D$7:$BH$7,CQ$8,$D21:$BH21) -> 1.111 | CS21: Total Thermal coal production at attributable basis | DM21: MLCCI-1639775051-92926 | DN21: MLCCI-1639775051-92926 | DO21: MLCCI-1639775051-92926 | EG21: MLCCI-1639775051-83982 | EH21: MLCCI-1639775051-83982 | EI21: MLCCI-1639775051-83982 | EJ21: MLCCI-1639775051-83982 | EK21: MLCCI-1639775051-95005 | EL21: MLCCI-1639775051-95005 | EM21: MLCCI-1639775051-95005 | EN21: MLCCI-1639775051-95005 | EO21: MLCCI-1639775051-105346 | EP21: MLCCI-1639775051-105346 | EQ21: MLCCI-1639775051-105346 | ER21: MLCCI-1639775051-105346 | ES21: MLCCI-1639775051-114893 | ET21: MLCCI-1639775051-114893 | EU21: MLCCI-1639775051-114893 | EV21: MLCCI-1639775051-125957 | EW21: MLCCI-1639775051-125957 | EX21: MLCCI-1639775051-125957 | EY21: MLCCI-1639775051-125957 | EZ21: MLCCI-1639775051-125957 | FA21: MLCCI-1639775051-133174 | FB21: MLCCI-1639775051-133174 | FC21: MLCCI-1639775051-133174 | FD21: MLCCI-1639775051-133174 | FE21: MLCCI-1066059444-50109 | FF21: MLCCI-1066059444-50109 | FG21: MLCCI-1066059444-50109 | FH21: MLCCI-1066059444-50109 | FI21: MLCCI-1066059444-57831 | FJ21: MLCCI-1066059444-57831 | FK21: MLCCI-1066059444-57831 | FL21: MLCCI-1066059444-57831
A23: ROM Production (Mine Level) | CF23: =SUM(CF10,CF12) -> 14.132898
A24: Dawson | B24: Mt | CH24: =SourcedData!CE13 -> 11.67297 | CI24: =SourcedData!CF13 -> 12.040414 | CJ24: =SourcedData!CG13 -> 10.022541 | CK24: =SourcedData!CH13 -> 9.35138 | CL24: =SourcedData!CI13 -> 10.27 | CM24: =SourcedData!CJ13 -> 9.508524 | FQ24: MLCCI-1639775051-95170 | FR24: MLCCI-1639775051-95170 | FS24: MLCCI-1639775051-95170 | FT24: MLCCI-1639775051-106959 | FU24: MLCCI-1639775051-106959 | FV24: MLCCI-1639775051-131028
A25: Lake Vermont | B25: Mt | CH25: =SourcedData!CE14 -> 11.084525 | CI25: =SourcedData!CF14 -> 11.05623 | CJ25: =SourcedData!CG14 -> 10.828616 | CK25: =SourcedData!CH14 -> 11.132 | CL25: =SourcedData!CI14 -> 11.16 | CN25: =SourcedData!CK14 -> 11.476069 | CO25: =SourcedData!CL14 -> 10.948135 | CP25: =SourcedData!CM14 -> 11.023168 | CQ25: =SourcedData!CN14 -> 10.840263 | FQ25: MLCCI-1639775051-95170 | FR25: MLCCI-1639775051-95170 | FS25: MLCCI-1639775051-95170 | FT25: MLCCI-1639775051-106959 | FU25: MLCCI-1639775051-106959 | FW25: MLCCI-1639775051-131028 | FX25: MLCCI-1639775051-131028 | FY25: MLCCI-1066059444-55194 | FZ25: MLCCI-1066059444-59780
A27: Mass Recovery
A28: Dawson | B28: % | BJ28: =BJ60/BJ47 -> 0.78180905 | BK28: =BK60/BK47 -> 0.72316413 | BM28: =BM60/BM47 -> 0.74555 | BN28: =BN60/BN47 -> 0.74654692 | BO28: =BO60/BO47 -> 0.74381582 | BP28: =BP60/BP47 -> 0.74860251 | BQ28: =BQ60/BQ47 -> 0.76860115 | BR28: =BR60/BR47 -> 0.76727844 | BS28: =BS60/BS47 -> 0.74160916 | BT28: =BT60/BT47 -> 0.76335247 | ... BV28: =BV60/BV47 -> 0.803367 | CH28: =CH12/CH24 -> 0.72473449 | CI28: =CI12/CI24 -> 0.7505279 | CJ28: =CJ12/CJ24 -> 0.73993994 | CK28: =CK12/CK24 -> 0.70860885 | CL28: =CL12/CL24 -> 0.74605266 | CM28: =CM12/CM24 -> 0.78645636 | CN28: =AVERAGE(BR28:BS28) -> 0.7544438 | CO28: =AVERAGE(BS28:BT28) -> 0.75248081 | CP28: =AVERAGE(BT28:BU28) -> 0.7439977 | CQ28: =AVERAGE(BU28:BV28) -> 0.76400497 | CS28: Mass recovery calculated using saleable and ROM production
A29: Jellinbah East | B29: % | BJ29: =BJ61/BJ55 -> 0.93006576 | BK29: =BK61/BK55 -> 0.91658341 | BM29: =BM61/BM55 -> 0.93979953 | BN29: =BN61/BN55 -> 0.9145903 | BR29: =BR61/BR55 -> 0.92758389 | BS29: =BS61/BS55 -> 0.8895058 | BT29: =BT61/BT55 -> 0.90910526 | BU29: =BU61/BU55 -> 0.87313528 | BV29: =BV61/BV55 -> 0.89797978
A30: Lake Vermont | B30: % | BJ30: =BJ62/BJ56 -> 0.82038073 | BK30: =BK62/BK56 -> 0.8157078 | BM30: =BM62/BM56 -> 0.79742371 | BN30: =BN62/BN56 -> 0.82025059 | BO30: =BO62/BO56 -> 0.82301498 | BP30: =BP62/BP56 -> 0.81839893 | BQ30: =BQ62/BQ56 -> 0.82508823 | BR30: =BR62/BR56 -> 0.84451541 | BS30: =BS62/BS56 -> 0.82829718 | BT30: =BT62/BT56 -> 0.81885645 | ... BV30: =BV62/BV56 -> 0.81180349 | CF30: =AVERAGE(BJ30:BK30) -> 0.81804426 | CH30: =CH152/CH25 -> 0.79029358 | CI30: =CI152/CI25 -> 0.82035631 | CJ30: =CJ152/CJ25 -> 0.81789095 | CK30: =CK152/CK25 -> 0.83136903 | CL30: =CL152/CL25 -> 0.79327957 | CN30: =CN152/CN25 -> 0.83577556 | CO30: =CO152/CO25 -> 0.82544168 | CP30: =CP152/CP25 -> 0.80403519 | CQ30: =CQ152/CQ25 -> 0.81626682 | CS30: Mass recovery calculated using saleable and ROM production. 2013 based on FY data
A32: Anglo's Share
A33: Aquila | B33: % | D33: =SourcedData!J15 -> 0.7 | E33: =SourcedData!K15 -> 0.7 | F33: =SourcedData!L15 -> 0.7 | G33: =SourcedData!M15 -> 0.7 | H33: =SourcedData!N15 -> 0.7 | I33: =SourcedData!O15 -> 0.7 | J33: =SourcedData!P15 -> 0.7 | K33: =SourcedData!Q15 -> 0.7 | ... BG33: =SourcedData!BM15 -> 0.7
A34: Callide | B34: % | D34: =SourcedData!J16 -> 1 | E34: =SourcedData!K16 -> 1 | F34: =SourcedData!L16 -> 1 | G34: =SourcedData!M16 -> 1 | H34: =SourcedData!N16 -> 1 | I34: =SourcedData!O16 -> 1 | J34: =SourcedData!P16 -> 1 | K34: =SourcedData!Q16 -> 1 | ... W34: =SourcedData!AC16 -> 1
A35: Dawson | B35: % | D35: =SourcedData!J17 -> 0.51 | E35: =SourcedData!K17 -> 0.51 | F35: =SourcedData!L17 -> 0.51 | G35: =SourcedData!M17 -> 0.51 | H35: =SourcedData!N17 -> 0.51 | I35: =SourcedData!O17 -> 0.51 | J35: =SourcedData!P17 -> 0.51 | K35: =SourcedData!Q17 -> 0.51 | ... BG35: =SourcedData!BM17 -> 0.51
A36: Drayton | B36: % | D36: =SourcedData!J18 -> 0.882 | E36: =SourcedData!K18 -> 0.882 | F36: =SourcedData!L18 -> 0.882 | G36: =SourcedData!M18 -> 0.882 | H36: =SourcedData!N18 -> 0.882 | I36: =SourcedData!O18 -> 0.882 | J36: =SourcedData!P18 -> 0.882 | K36: =SourcedData!Q18 -> 0.882 | ... W36: =SourcedData!AC18 -> 0.882
A37: Foxleigh | B37: % | D37: =SourcedData!J19 -> 0.7 | E37: =SourcedData!K19 -> 0.7 | F37: =SourcedData!L19 -> 0.7 | G37: =SourcedData!M19 -> 0.7 | H37: =SourcedData!N19 -> 0.7 | I37: =SourcedData!O19 -> 0.7 | J37: =SourcedData!P19 -> 0.7 | K37: =SourcedData!Q19 -> 0.7 | ... V37: =SourcedData!AB19 -> 0.7
A38: Grasstree | B38: % | D38: =SourcedData!J20 -> 0.7 | E38: =SourcedData!K20 -> 0.7 | F38: =SourcedData!L20 -> 0.7 | G38: =SourcedData!M20 -> 0.7 | H38: =SourcedData!N20 -> 0.7 | I38: =SourcedData!O20 -> 0.7 | J38: =SourcedData!P20 -> 0.7 | K38: =SourcedData!Q20 -> 0.7 | ... AR38: =SourcedData!AX20 -> 0.7
A39: Grosvenor | B39: % | D39: =SourcedData!J21 -> 1 | E39: =SourcedData!K21 -> 1 | F39: =SourcedData!L21 -> 1 | G39: =SourcedData!M21 -> 1 | H39: =SourcedData!N21 -> 1 | I39: =SourcedData!O21 -> 1 | J39: =SourcedData!P21 -> 1 | K39: =SourcedData!Q21 -> 1 | ... BC39: =SourcedData!BI21 -> 0.88
A40: Jellinbah East | B40: % | D40: =SourcedData!J22 -> 0.233 | E40: =SourcedData!K22 -> 0.233 | F40: =SourcedData!L22 -> 0.233 | G40: =SourcedData!M22 -> 0.233 | H40: =SourcedData!N22 -> 0.233 | I40: =SourcedData!O22 -> 0.233 | J40: =SourcedData!P22 -> 0.233 | K40: =SourcedData!Q22 -> 0.233 | ... BC40: =SourcedData!BI22 -> 0.233
A41: Lake Lindsay | B41: % | D41: =SourcedData!J23 -> 0.768 | E41: =SourcedData!K23 -> 0.768 | F41: =SourcedData!L23 -> 0.768 | G41: =SourcedData!M23 -> 0.768 | H41: =SourcedData!N23 -> 0.775 | I41: =SourcedData!O23 -> 0.775 | J41: =SourcedData!P23 -> 0.775 | K41: =SourcedData!Q23 -> 0.775 | ... BG41: =SourcedData!BM23 -> 0.792
A42: Lake Vermont | B42: % | D42: =SourcedData!J24 -> 0.233 | E42: =SourcedData!K24 -> 0.233 | F42: =SourcedData!L24 -> 0.233 | G42: =SourcedData!M24 -> 0.233 | H42: =SourcedData!N24 -> 0.233 | I42: =SourcedData!O24 -> 0.233 | J42: =SourcedData!P24 -> 0.233 | K42: =SourcedData!Q24 -> 0.233 | ... BC42: =SourcedData!BI24 -> 0.233
A43: Moranbah North | B43: % | D43: =SourcedData!J25 -> 0.88 | E43: =SourcedData!K25 -> 0.88 | F43: =SourcedData!L25 -> 0.88 | G43: =SourcedData!M25 -> 0.88 | H43: =SourcedData!N25 -> 0.88 | I43: =SourcedData!O25 -> 0.88 | J43: =SourcedData!P25 -> 0.88 | K43: =SourcedData!Q25 -> 0.88 | ... BC43: =SourcedData!BI25 -> 0.88
A45: FY Production ROM Production (Mine level)
A46: ROM Production
...

Sheet VariousOperations_Employees
A1: Anglo American Coal - Employee Calculations
A3: Color Legend
A4: Sourced datapoint
A5: Calculation
A6: Assumption
B7: Quarterly Coal Mine Employees | BS7: Source
B8: 2012 | C8: 2012 | D8: 2012 | E8: 2012 | F8: 2013 | G8: 2013 | H8: 2013 | I8: 2013 | J8: 2014 | K8: 2014 | L8: 2014 | M8: 2014 | N8: 2015 | O8: 2015 | P8: 2015 | Q8: 2015 | R8: 2016 | S8: 2016 | T8: 2016 | U8: 2016 | V8: 2017 | W8: 2017 | X8: 2017 | Y8: 2017 | Z8: 2018 | AA8: 2018 | AB8: 2018 | AC8: 2018 | AD8: 2019 | AE8: 2019 | AF8: 2019 | AG8: 2019 | AH8: 2020 | AI8: 2020 | AJ8: 2020 | AK8: 2020 | AL8: 2021 | AM8: 2021 | AN8: 2021 | AO8: 2021 | AP8: 2022 | AQ8: 2022 | AR8: 2022 | AS8: 2022 | AT8: 2023 | AU8: 2023 | AV8: 2023 | AW8: 2023 | AX8: 2024 | AY8: 2024 | AZ8: 2024 | BA8: 2024 | BS8: 2012 | BT8: 2012 | BU8: 2012 | BV8: 2012 | BW8: 2013 | BX8: 2013 | BY8: 2013 | BZ8: 2013 | CA8: 2014 | CB8: 2014 | CC8: 2014 | CD8: 2014 | CE8: 2015 | CF8: 2015 | CG8: 2015 | CH8: 2015 | CI8: 2016 | CJ8: 2016 | CK8: 2016 | CL8: 2016 | CM8: 2017 | CN8: 2017 | CO8: 2017 | CP8: 2017 | CQ8: 2018 | CR8: 2018 | CS8: 2018 | CT8: 2018 | CU8: 2019 | CV8: 2019 | CW8: 2019 | CX8: 2019 | CY8: 2020 | CZ8: 2020 | DA8: 2020 | DB8: 2020 | DC8: 2021 | DD8: 2021 | DE8: 2021 | DF8: 2021 | DG8: 2022 | DH8: 2022 | DI8: 2022 | DJ8: 2022 | DK8: 2023 | DL8: 2023 | DM8: 2023 | DN8: 2023 | DO8: 2024 | DP8: 2024 | DQ8: 2024 | DR8: 2024
B9: Q1 | C9: Q2 | D9: Q3 | E9: Q4 | F9: Q1 | G9: Q2 | H9: Q3 | I9: Q4 | J9: Q1 | K9: Q2 | L9: Q3 | M9: Q4 | N9: Q1 | O9: Q2 | P9: Q3 | Q9: Q4 | R9: Q1 | S9: Q2 | T9: Q3 | U9: Q4 | V9: Q1 | W9: Q2 | X9: Q3 | Y9: Q4 | Z9: Q1 | AA9: Q2 | AB9: Q3 | AC9: Q4 | AD9: Q1 | AE9: Q2 | AF9: Q3 | AG9: Q4 | AH9: Q1 | AI9: Q2 | AJ9: Q3 | AK9: Q4 | AL9: Q1 | AM9: Q2 | AN9: Q3 | AO9: Q4 | AP9: Q1 | AQ9: Q2 | AR9: Q3 | AS9: Q4 | AT9: Q1 | AU9: Q2 | AV9: Q3 | AW9: Q4 | AX9: Q1 | AY9: Q2 | AZ9: Q3 | BA9: Q4 | BC9: 2012 | BD9: 2013 | BE9: 2014 | BF9: 2015 | BG9: 2016 | BH9: 2017 | BI9: 2018 | BJ9: 2019 | BK9: 2020 | BL9: 2021 | BM9: 2022 | BN9: 2023 | BO9: 2024 | BQ9: Comment/Description | BS9: Q1 | BT9: Q2 | BU9: Q3 | BV9: Q4 | BW9: Q1 | BX9: Q2 | BY9: Q3 | BZ9: Q4 | CA9: Q1 | CB9: Q2 | CC9: Q3 | CD9: Q4 | CE9: Q1 | CF9: Q2 | CG9: Q3 | CH9: Q4 | CI9: Q1 | CJ9: Q2 | CK9: Q3 | CL9: Q4 | CM9: Q1 | CN9: Q2 | CO9: Q3 | CP9: Q4 | CQ9: Q1 | CR9: Q2 | CS9: Q3 | CT9: Q4 | CU9: Q1 | CV9: Q2 | CW9: Q3 | CX9: Q4 | CY9: Q1 | CZ9: Q2 | DA9: Q3 | DB9: Q4 | DC9: Q1 | DD9: Q2 | DE9: Q3 | DF9: Q4 | DG9: Q1 | DH9: Q2 | DI9: Q3 | DJ9: Q4 | DK9: Q1 | DL9: Q2 | DM9: Q3 | DN9: Q4 | DO9: Q1 | DP9: Q2 | DQ9: Q3 | DR9: Q4
A10: Coal Mines - Australia
A11: Employees
A12: Dawson | B12: =SourcedData!J91 -> 1927 | C12: =SourcedData!K91 -> 1618 | D12: =SourcedData!L91 -> 1632 | E12: =SourcedData!M91 -> 1563 | F12: =SourcedData!N91 -> 1522 | G12: =SourcedData!O91 -> 1577 | H12: =SourcedData!P91 -> 1768 | I12: =SourcedData!Q91 -> 1481 | ... BA12: =SourcedData!BI91 -> 1603 | BC12: =AVERAGEIF($B$8:$AC$8,BC$9,$B12:$AC12) -> 1685 | BD12: =AVERAGEIF($B$8:$AC$8,BD$9,$B12:$AC12) -> 1587 | BE12: =AVERAGEIF($B$8:$AC$8,BE$9,$B12:$AC12) -> 1280.75 | BF12: =AVERAGEIF($B$8:$AC$8,BF$9,$B12:$AC12) -> 1305 | BG12: =AVERAGEIF($B$8:$AC$8,BG$9,$B12:$AC12) -> 1221 | BH12: =AVERAGEIF($B$8:$AC$8,BH$9,$B12:$AC12) -> 1253 | BI12: =AVERAGEIF($B$8:$AC$8,BI$9,$B12:$AC12) -> 1416.25 | BJ12: =AVERAGEIF($B$8:$AG$8,BJ$9,$B12:$AG12) -> 1525.25 | BK12: =AVERAGEIF($B$8:$AK$8,BK$9,$B12:$AK12) -> 1489.75 | BL12: =AVERAGEIF($B$8:$BA$8,BL$9,$B12:$BA12) -> 1421 | BM12: =AVERAGEIF($B$8:$BA$8,BM$9,$B12:$BA12) -> 1423.5 | BN12: =AVERAGEIF($B$8:$BA$8,BN$9,$B12:$BA12) -> 1468.75 | BO12: =AVERAGEIF($B$8:$BA$8,BO$9,$B12:$BA12) -> 1565.75 | BQ12: Average of quarterly employees numbers | BS12: MLCCI-991351766-4929 | BT12: MLCCI-991351766-4929 | BU12: MLCCI-991351766-4929 | BV12: MLCCI-991351766-4929 | BW12: MLCCI-991351766-4929 | BX12: MLCCI-991351766-4929 | BY12: MLCCI-991351766-4929 | BZ12: MLCCI-991351766-4929 | CA12: MLCCI-991351766-4929 | CB12: MLCCI-991351766-4929 | CC12: MLCCI-991351766-4929 | CD12: MLCCI-991351766-4929 | CE12: MLCCI-991351766-4929 | CF12: MLCCI-991351766-4929 | CG12: MLCCI-991351766-4929 | CH12: MLCCI-991351766-4929 | CI12: MLCCI-1639775051-90659 | CJ12: MLCCI-1639775051-90659 | CK12: MLCCI-1639775051-90659 | CL12: MLCCI-1639775051-90659 | CM12: MLCCI-1639775051-90659 | CN12: MLCCI-1639775051-90659 | CO12: MLCCI-1639775051-90659 | CP12: MLCCI-1639775051-90659 | CQ12: MLCCI-1639775051-100323 | CR12: MLCCI-1639775051-100323 | CS12: MLCCI-1639775051-100323 | CT12: MLCCI-1639775051-100323 | CU12: MLCCI-1639775051-116522 | CV12: MLCCI-1639775051-116522 | CW12: MLCCI-1639775051-116522 | CX12: MLCCI-1639775051-116522 | CY12: MLCCI-1639775051-117119 | CZ12: MLCCI-1639775051-117119 | DA12: MLCCI-1639775051-117119 | DB12: MLCCI-1639775051-117119 | DC12: MLCCI-1639775051-125834 | DD12: MLCCI-1639775051-125834 | DE12: MLCCI-1639775051-125834 | DF12: MLCCI-1639775051-125834 | DG12: MLCCI-1639775051-125834 | DH12: MLCCI-1639775051-125834 | DI12: MLCCI-1639775051-125834 | DJ12: MLCCI-1639775051-125834 | DK12: MLCCI-1066059444-53291 | DL12: MLCCI-1066059444-53291 | DM12: MLCCI-1066059444-53291 | DN12: MLCCI-1066059444-53291 | DO12: MLCCI-1066059444-53291 | DP12: MLCCI-1066059444-53291 | DQ12: MLCCI-1066059444-53291 | DR12: MLCCI-1066059444-53291
